<?xml version="1.0" encoding="UTF-8"?>
<sdf version="1.9">
  <model name="cloudship">
    <self_collide>false</self_collide>
    <static>false</static>
    <link name="hull">
      <pose>-0.1299999999999999 0 2 0 0 0</pose>
      <inertial>
        <pose>0.023862743087597126 0 -0.4953798831128884 0 0 0</pose>
        <mass>7.314749999999999</mass>
        <inertia>
          <ixx>5.7971517083333333</ixx>
          <ixy>0</ixy>
          <ixz>0</ixz>
          <iyy>4.958383606533334</iyy>
          <iyz>0</iyz>
          <izz>7.985372374533334</izz>
        </inertia>
      </inertial>

      <sensor name="imu_sensor" type="imu">
        <always_on>1</always_on>
        <update_rate>250</update_rate>
        <imu>
          <angular_velocity>
            <x>
              <noise type="gaussian">
                <mean>0</mean>
                <stddev>0.0003394</stddev>
                <dynamic_bias_stddev>3.8785e-05</dynamic_bias_stddev>
                <dynamic_bias_correlation_time>1000</dynamic_bias_correlation_time>
              </noise>
            </x>
            <y>
              <noise type="gaussian">
                <mean>0</mean>
                <stddev>0.0003394</stddev>
                <dynamic_bias_stddev>3.8785e-05</dynamic_bias_stddev>
                <dynamic_bias_correlation_time>1000</dynamic_bias_correlation_time>
              </noise>
            </y>
            <z>
              <noise type="gaussian">
                <mean>0</mean>
                <stddev>0.0003394</stddev>
                <dynamic_bias_stddev>3.8785e-05</dynamic_bias_stddev>
                <dynamic_bias_correlation_time>1000</dynamic_bias_correlation_time>
              </noise>
            </z>
          </angular_velocity>
          <linear_acceleration>
            <x>
              <noise type="gaussian">
                <mean>0</mean>
                <stddev>0.004</stddev>
                <dynamic_bias_stddev>0.006</dynamic_bias_stddev>
                <dynamic_bias_correlation_time>300</dynamic_bias_correlation_time>
              </noise>
            </x>
            <y>
              <noise type="gaussian">
                <mean>0</mean>
                <stddev>0.004</stddev>
                <dynamic_bias_stddev>0.006</dynamic_bias_stddev>
                <dynamic_bias_correlation_time>300</dynamic_bias_correlation_time>
              </noise>
            </y>
            <z>
              <noise type="gaussian">
                <mean>0</mean>
                <stddev>0.004</stddev>
                <dynamic_bias_stddev>0.006</dynamic_bias_stddev>
                <dynamic_bias_correlation_time>300</dynamic_bias_correlation_time>
              </noise>
            </z>
          </linear_acceleration>
        </imu>
      </sensor>
      <sensor name="air_pressure_sensor" type="air_pressure">
        <always_on>1</always_on>
        <update_rate>50</update_rate>
        <air_pressure>
          <pressure>
            <noise type="gaussian">
              <mean>0</mean>
              <stddev>0.01</stddev>
            </noise>
          </pressure>
        </air_pressure>
      </sensor>
      <sensor name="navsat_sensor" type="navsat">
        <always_on>1</always_on>
        <update_rate>30</update_rate>
      </sensor>

      <gravity>true</gravity>
      <self_collide>false</self_collide>
      <velocity_decay/>

      <visual name="hull_visual">
        <geometry>
          <mesh>
            <scale>2.35 0.8 0.8</scale>
            <uri>model://cloudship/meshes/ellipsoid.stl</uri>
          </mesh>
        </geometry>
      </visual>
      <collision name="hull_collision">
        <pose>0 0 0 0 0 0</pose>
        <geometry>
          <mesh>
            <scale>2.35 0.8 0.8</scale>
            <uri>model://cloudship/meshes/ellipsoid.stl</uri>
          </mesh>
        </geometry>
      </collision>

      <visual name="gondola_visual">
        <pose>0.2200000000000002 0 -0.7986 0 0 0</pose>
        <geometry>
          <box>
            <size>0.4 0.17 0.2</size>
          </box>
        </geometry>
      </visual>
      <collision name="gondola_collision">
        <pose>0.2200000000000002 0 -0.8486 0 0 0</pose>
        <geometry>
          <box>
            <size>0.4 0.17 0.1</size>
          </box>
        </geometry>
      </collision>

      <visual name="payload_visual">
      <pose>-0.17999999999999972 0 -0.784 1.5707963267948966 0 0</pose>
        <geometry>
          <cylinder>
            <radius>0.05</radius>
            <length>0.1</length>
          </cylinder>
        </geometry>
      </visual>
      <collision name="payload_collision">
        <pose>-0.17999999999999972 0 -0.784 1.5707963267948966 0 0</pose>
        <geometry>
          <cylinder>
            <radius>0.05</radius>
            <length>0.1</length>
          </cylinder>
        </geometry>
      </collision>

      <visual name="fin_top_visual">
        <pose>-1.8799999999999994 0 0.3684 0 0 0</pose>
        <geometry>
          <box>
            <size>0.465 0.01 0.78</size>
          </box>
        </geometry>
      </visual>
      <collision name="fin_top_collision">
        <pose>-1.8799999999999994 0 0.3684 0 0 0</pose>
        <geometry>
          <box>
            <size>0.465 0.01 0.78</size>
          </box>
        </geometry>
      </collision>

      <visual name="fin_port_visual">
        <pose>-1.8799999999999994 0.3684 0 -1.5707963267948966 0 0</pose>
        <geometry>
          <box>
            <size>0.465 0.01 0.78</size>
          </box>
        </geometry>
      </visual>
      <collision name="fin_port_collision">
        <pose>-1.8799999999999994 0.3684 0 -1.5707963267948966 0 0</pose>
          <geometry>
          <box>
            <size>0.465 0.01 0.78</size>
          </box>
        </geometry>
      </collision>

      <visual name="fin_sb_visual">
        <pose>-1.8799999999999994 -0.3684 0 1.5707963267948966 0 0</pose>
        <geometry>
          <box>
            <size>0.465 0.01 0.78</size>
          </box>
        </geometry>
      </visual>
      <collision name="fin_sb_collision">
        <pose>-1.8799999999999994 -0.3684 0 1.5707963267948966 0 0</pose>
        <geometry>
          <box>
            <size>0.465 0.01 0.78</size>
          </box>
        </geometry>
      </collision>

      <visual name="fin_bottom_rotor_visual">
        <pose>-1.8799999999999994 0 -0.7584 0 0 0</pose>
        <geometry>
          <mesh>
            <scale>0.465 0.01 0.39</scale>
            <uri>model://cloudship/meshes/fin_prop.stl</uri>
          </mesh>
        </geometry>
      </visual>

      <visual name="fin_bottom_plate_visual">
        <pose>-1.8799999999999994 0 -0.1734 0 0 0</pose>
        <geometry>
          <box>
            <size>0.465 0.01 0.39</size>
          </box>
        </geometry>
      </visual>

      <collision name="fin_bottom_collision">
        <pose>-1.8799999999999994 0 -0.7584 0 0 0</pose>
        <geometry>
          <mesh>
            <scale>0.465 0.01 0.39</scale>
            <uri>model://cloudship/meshes/fin_prop.stl</uri>
          </mesh>
        </geometry>
      </collision>
    </link>


    <link name="thrusters_rod">
      <pose>0.19000000000000017 0 2.2514000000000003 0 0 0</pose><inertial>
        <mass>0.5</mass>
        <inertia>
          <ixx>0.0337625</ixx>
          <iyy>2.5e-05</iyy>
          <izz>0.0337625</izz>
        </inertia>
      </inertial>

      <gravity>false</gravity>
      <self_collide>false</self_collide>
      <velocity_decay/>

      <visual name="thrusters_rod_visual">
        <pose>0 0 0 1.5707963267948966 0 0</pose>
        <geometry>
          <cylinder>
            <radius>0.01</radius>
            <length>0.9</length>
          </cylinder>
        </geometry>
      </visual>
      <visual name="port_prop_gaurd_visual">
        <pose>0.02 0.45 0 0 1.5707963267948966 0</pose>
        <geometry>
          <mesh>
            <scale>0.18161000000000002 0.18161000000000002 0.02</scale>
            <uri>model://cloudship/meshes/prop_gaurd.stl</uri>
          </mesh>
        </geometry>
      </visual>
      <visual name="sb_prop_gaurd_visual">
        <pose>0.02 -0.45 0 0 1.5707963267948966 0</pose>
        <geometry>
          <mesh>
            <scale>0.18161000000000002 0.18161000000000002 0.02</scale>
            <uri>model://cloudship/meshes/prop_gaurd.stl</uri>
          </mesh>
        </geometry>
      </visual>

      <collision name="thrusters_rod_port_collision">
        <pose>0 0.2675 0 1.5707963267948966 0 0</pose>
        <geometry>
          <cylinder>
            <radius>0.01</radius>
            <length>0.365</length>
          </cylinder>
        </geometry>
      </collision>
      <collision name="thrusters_rod_sb_collision">
        <pose>0 -0.2675 0 1.5707963267948966 0 0</pose>
        <geometry>
          <cylinder>
            <radius>0.01</radius>
            <length>0.365</length>
          </cylinder>
        </geometry>
      </collision>
    </link>

    <joint name='thrusters_rod_joint' type='revolute'>
      <parent>hull</parent>
      <child>thrusters_rod</child>
      <axis>
        <xyz>0 1 0</xyz>
        <limit>
          <lower>-3.141592653589793</lower>
          <upper>3.141592653589793</upper>
        </limit>
        <dynamics>
          <damping>0.1</damping>
        </dynamics>
      </axis>
      <physics>
        <ode>
          <implicit_spring_damper>1</implicit_spring_damper>
        </ode>
      </physics>
    </joint>


    <link name="rotor_0">
      <pose>0.2100000000000002 0.45 2.2464 0 1.5707963267948966 0</pose>
      <inertial>
        <mass>0.0025</mass>
        <inertia>
          <ixx>1.0000000000000002e-06</ixx>
          <iyy>2.2798341666666663e-05</iyy>
          <izz>2.2798341666666663e-05</izz>
        </inertia>
      </inertial>

      <gravity>false</gravity>
      <self_collide>false</self_collide>
      <velocity_decay/>

      <visual name="rotor_0_visual">
        <geometry>
          <mesh>
            <scale>1.2842752129438761 1.2842752129438761 2.0855057351407718</scale>
            <uri>model://cloudship/meshes/prop_ccw.dae</uri>
          </mesh>
        </geometry>
      </visual>

      <collision name="rotor_0_collision">
        <geometry>
          <cylinder>
            <length>0.02</length>
            <radius>0.1651</radius>
          </cylinder>
        </geometry>
      </collision>
    </link>

    <joint name='rotor_0_joint' type='revolute'>
      <child>rotor_0</child>
      <parent>thrusters_rod</parent>
      <axis>
        <xyz>0 0 1</xyz>
        <limit>
          <lower>-1e+16</lower>
          <upper>1e+16</upper>
        </limit>
        <dynamics>
          <spring_reference>0</spring_reference>
          <spring_stiffness>0</spring_stiffness>
        </dynamics>
      </axis>
    </joint>

    <plugin filename="gz-sim-multicopter-motor-model-system" name="gz::sim::systems::MulticopterMotorModel">
      <jointName>rotor_0_joint</jointName>
      <linkName>rotor_0</linkName>
      <turningDirection>ccw</turningDirection>
      <timeConstantUp>0.05</timeConstantUp>
      <timeConstantDown>0.05</timeConstantDown>
      <maxRotVelocity>1500</maxRotVelocity>
      <motorConstant>7.063200000000001e-06</motorConstant>
      <momentConstant>0</momentConstant>
      <commandSubTopic>command/motor_speed</commandSubTopic>
      <motorNumber>0</motorNumber>
      <rotorDragCoefficient>0.000806428</rotorDragCoefficient>
      <rollingMomentCoefficient>1e-06</rollingMomentCoefficient>
      <rotorVelocitySlowdownSim>10</rotorVelocitySlowdownSim>
      <motorType>velocity</motorType>
    </plugin>

    <link name="rotor_1">
      <pose>0.2100000000000002 -0.45 2.2514000000000003 0 1.5707963267948966 0</pose>
      <inertial>
        <mass>0.0025</mass>
        <inertia>
          <ixx>1.0000000000000002e-06</ixx>
          <iyy>2.2798341666666663e-05</iyy>
          <izz>2.2798341666666663e-05</izz>
        </inertia>
      </inertial>

      <gravity>false</gravity>
      <self_collide>false</self_collide>
      <velocity_decay/>

      <visual name="rotor_1_visual">
        <geometry>
          <mesh>
            <scale>1.2842752129438761 1.2842752129438761 2.0855057351407718</scale>
            <uri>model://cloudship/meshes/prop_cw.dae</uri>
          </mesh>
        </geometry>
      </visual>

      <collision name="rotor_1_collision">
        <geometry>
          <cylinder>
            <length>0.02</length>
            <radius>0.1651</radius>
          </cylinder>
        </geometry>
      </collision>
    </link>

    <joint name='rotor_1_joint' type='revolute'>
      <child>rotor_1</child>
      <parent>thrusters_rod</parent>
      <axis>
        <xyz>0 0 1</xyz>
        <limit>
          <lower>-1e+16</lower>
          <upper>1e+16</upper>
        </limit>
        <dynamics>
          <spring_reference>0</spring_reference>
          <spring_stiffness>0</spring_stiffness>
        </dynamics>
      </axis>
    </joint>

    <plugin filename="gz-sim-multicopter-motor-model-system" name="gz::sim::systems::MulticopterMotorModel">
      <jointName>rotor_1_joint</jointName>
      <linkName>rotor_1</linkName>
      <turningDirection>cw</turningDirection>
      <timeConstantUp>0.05</timeConstantUp>
      <timeConstantDown>0.05</timeConstantDown>
      <maxRotVelocity>1500</maxRotVelocity>
      <motorConstant>7.063200000000001e-06</motorConstant>
      <momentConstant>0</momentConstant>
      <commandSubTopic>command/motor_speed</commandSubTopic>
      <motorNumber>1</motorNumber>
      <rotorDragCoefficient>0.000806428</rotorDragCoefficient>
      <rollingMomentCoefficient>1e-06</rollingMomentCoefficient>
      <rotorVelocitySlowdownSim>10</rotorVelocitySlowdownSim>
      <motorType>velocity</motorType>
    </plugin>

    <link name="rotor_2">
      <pose>-2.0099999999999993 0 2.5366 1.5707963267948966 0 0</pose>
      <inertial>
        <mass>0.0015</mass>
        <inertia>
          <ixx>6.000000000000001e-07</ixx>
          <iyy>2.0661250000000005e-06</iyy>
          <izz>2.0661250000000005e-06</izz>
        </inertia>
      </inertial>

      <gravity>false</gravity>
      <self_collide>false</self_collide>
      <velocity_decay/>

      <visual name="rotor_2_visual">
        <geometry>
          <mesh>
            <scale>0.4939520049784139 0.4939520049784139 2.0855057351407718</scale>
            <uri>model://cloudship/meshes/prop_cw.dae</uri>
          </mesh>
        </geometry>
      </visual>

      <collision name="rotor_2_collision">
        <geometry>
          <cylinder>
            <length>0.02</length>
            <radius>0.0635</radius>
          </cylinder>
        </geometry>
      </collision>
    </link>

    <joint name='rotor_2_joint' type='revolute'>
      <child>rotor_2</child>
      <parent>hull</parent>
      <axis>
        <xyz>0 0 1</xyz>
        <limit>
          <lower>-1e+16</lower>
          <upper>1e+16</upper>
        </limit>
        <dynamics>
          <spring_reference>0</spring_reference>
          <spring_stiffness>0</spring_stiffness>
        </dynamics>
      </axis>
    </joint>

    <plugin filename="gz-sim-multicopter-motor-model-system" name="gz::sim::systems::MulticopterMotorModel">
      <jointName>rotor_2_joint</jointName>
      <linkName>rotor_2</linkName>
      <turningDirection>cw</turningDirection>
      <timeConstantUp>0.025</timeConstantUp>
      <timeConstantDown>0.025</timeConstantDown>
      <maxRotVelocity>1500</maxRotVelocity>
      <motorConstant>1.0464e-06</motorConstant>
      <momentConstant>0</momentConstant>
      <commandSubTopic>command/motor_speed</commandSubTopic>
      <motorNumber>2</motorNumber>
      <rotorDragCoefficient>0.000806428</rotorDragCoefficient>
      <rollingMomentCoefficient>1e-06</rollingMomentCoefficient>
      <rotorVelocitySlowdownSim>10</rotorVelocitySlowdownSim>
      <motorType>velocity</motorType>
    </plugin>

  </model>
</sdf>
